<?xml version="1.0" encoding="UTF-8"?>
<testsuite name="sele_tests.ResTest-20201213221526" tests="1" file="sele_tests.py" time="0.005" timestamp="2020-12-13T22:15:26" failures="0" errors="1" skipped="0">
	<testcase classname="sele_tests.ResTest" name="test_should_issue_res_message" time="0.005" timestamp="2020-12-13T22:15:26">
		<error type="AttributeError" message="'capstone' object has no attribute 'driver'"><![CDATA[Traceback (most recent call last):
  File "c:\python38-32\lib\unittest\case.py", line 60, in testPartExecutor
    yield
  File "c:\python38-32\lib\unittest\case.py", line 676, in run
    self._callTestMethod(testMethod)
  File "c:\python38-32\lib\unittest\case.py", line 633, in _callTestMethod
    method()
  File "c:\users\hp\desktop\cp\src\unittest\python\sele_tests.py", line 10, in test_should_issue_res_message
    x = Rs(out)
  File "c:\users\hp\desktop\cp\src\main\python\sele.py", line 74, in Rs
    x.append(c.test_url(),c.test_explore_button(),c.test_login_correct(),c.test_product(),c.test_negotiate_button())
  File "c:\users\hp\desktop\cp\src\main\python\sele.py", line 13, in test_url
    self.driver.get("http://127.0.0.1:8000/")
AttributeError: 'capstone' object has no attribute 'driver'
]]></error>
	</testcase>
</testsuite>
